<?xml version="1.0" encoding="utf-8"?>
<!-- This URDF was automatically created by SolidWorks to URDF Exporter! Originally created by Stephen Brawner (brawner@gmail.com) 
     Commit Version: 1.6.0-1-g15f4949  Build Version: 1.6.7594.29634
     For more information, please see http://wiki.ros.org/sw_urdf_exporter -->
<robot
  name="car_robot" xmlns:xacro="http://www.ros.org/wiki/xacro">
  
  <!--BASE LINK-->
  <link
    name="base_link">
  </link>

  <!--BODY LINK-->
  <link
    name="body_link">
    <inertial>
      <origin
        xyz="0.36349 1.4572E-16 -0.015035"
        rpy="0 0 0" />
      <mass
        value="0.5" />
      <inertia
        ixx="0.26971"
        ixy="-2.3725E-16"
        ixz="0.015148"
        iyy="0.56137"
        iyz="1.4744E-18"
        izz="0.80926" />
    </inertial>
    <visual>
      <origin
        xyz="0 0 0"
        rpy="0 0 0" />
      <geometry>
        <mesh
          filename="package://robot_package/meshes/body_link.STL" />
      </geometry>
      <material
        name="">
        <color
          rgba="1 0.16863 0.16863 1" />
      </material>
    </visual>
    <collision>
      <origin
        xyz="0 0 0"
        rpy="0 0 0" />
      <geometry>
        <mesh
          filename="package://robot_package/meshes/body_link.STL" />
      </geometry>
    </collision>
  </link>

  <!--BODY JOINT-->
  <joint
    name="body_joint"
    type="fixed">
    <origin
      xyz="-0.1 0 0.17"
      rpy="0 0 0" />
    <parent
      link="base_link" />
    <child
      link="body_link" />
    <axis
      xyz="0 0 0" />
  </joint>

  <!--LEFT WHEEL LINK-->
  <link
    name="left_wheel_link">
    <inertial>
      <origin
        xyz="0 0 2.7756E-17"
        rpy="0 0 0" />
      <mass
        value="0.2" />
      <inertia
        ixx="0.014689"
        ixy="-3.8877E-18"
        ixz="1.5807E-18"
        iyy="0.014689"
        iyz="1.3228E-19"
        izz="0.02783" />
    </inertial>
    <visual>
      <origin
        xyz="0 0 0"
        rpy="0 0 0" />
      <geometry>
        <mesh
          filename="package://robot_package/meshes/left_wheel_link.STL" />
      </geometry>
      <material
        name="">
        <color
          rgba="0.039216 0.4902 0.7098 1" />
      </material>
    </visual>
    <collision>
      <origin
        xyz="0 0 0"
        rpy="0 0 0" />
      <geometry>
        <mesh
          filename="package://robot_package/meshes/left_wheel_link.STL" />
      </geometry>
    </collision>
  </link>

  <!--LEFT WHEEL JOINT-->
  <joint
    name="left_wheel_joint"
    type="continuous">
    <origin
      xyz="0.1 0.235 -0.02"
      rpy="-1.5708 0 0" />
    <parent
      link="body_link" />
    <child
      link="left_wheel_link" />
    <axis
      xyz="0 0 1" />
  </joint>

  <!--RIGHT WHEEL LINK-->
  <link
    name="right_wheel_link">
    <inertial>
      <origin
        xyz="-1.1102E-16 5.5511E-17 0"
        rpy="0 0 0" />
      <mass
        value="0.2" />
      <inertia
        ixx="0.014689"
        ixy="-2.9531E-18"
        ixz="-5.4263E-19"
        iyy="0.014689"
        iyz="-7.4614E-19"
        izz="0.02783" />
    </inertial>
    <visual>
      <origin
        xyz="0 0 0"
        rpy="0 0 0" />
      <geometry>
        <mesh
          filename="package://robot_package/meshes/right_wheel_link.STL" />
      </geometry>
      <material
        name="">
        <color
          rgba="0.039216 0.4902 0.7098 1" />
      </material>
    </visual>
    <collision>
      <origin
        xyz="0 0 0"
        rpy="0 0 0" />
      <geometry>
        <mesh
          filename="package://robot_package/meshes/right_wheel_link.STL" />
      </geometry>
    </collision>
  </link>

  <!--RIGHT WHEEL JOINT-->
  <joint
    name="right_wheel_joint"
    type="continuous">
    <origin
      xyz="0.1 -0.235 -0.02"
      rpy="1.5708 0 0" />
    <parent
      link="body_link" />
    <child
      link="right_wheel_link" />
    <axis
      xyz="0 0 -1" />
  </joint>

  <!--CASTER WHEEL LINK-->
  <link
    name="caster_wheel_link">
    <inertial>
      <origin
        xyz="0 0 0"
        rpy="0 0 0" />
      <mass
        value="0.1" />
      <inertia
        ixx="0"
        ixy="0"
        ixz="0"
        iyy="0"
        iyz="0"
        izz="0" />
    </inertial>
    <visual>
      <origin
        xyz="0 0 0"
        rpy="0 0 0" />
      <geometry>
        <mesh
          filename="package://robot_package/meshes/caster_wheel_link.STL" />
      </geometry>
      <material
        name="">
        <color
          rgba="0.34118 0.83922 0.41176 1" />
      </material>
    </visual>
    <collision>
      <origin
        xyz="0 0 0"
        rpy="0 0 0" />
      <geometry>
      <!--
        <mesh
          filename="package://robot_package/meshes/caster_wheel_link.STL" />
        -->
        <sphere
          radius="0.15"
          length="0.01" />
        <surface>
          <friction>
            <ode>
              <mu>0.001</mu>
              <mu1>0.001</mu1>
              <mu2>0.001</mu2>
              <slip1>1.0</slip1>
              <slip2>1.0</slip2>
            </ode>
          </friction>
        </surface>
      </geometry>
    </collision>
  </link>

  <!--CASTER WHEEL JOINT-->
   <joint
    name="caster_wheel_joint"
    type="fixed">
    <origin
      xyz="0.53 0 -0.03"
      rpy="0 0 0" />
    <parent
      link="body_link" />
    <child
      link="caster_wheel_link" />
    <axis
      xyz="0 0 0" />
    <dynamics
      damping="0"
      friction="0" />
  </joint>
  
  <!-- CASTER WHEEL NULOVE TRENI -->
  <gazebo reference='caster_wheel_link'>
    <mu>0.0</mu>
    <mu1>0.0</mu1>
    <mu2>0.0</mu2>
  </gazebo>

  <!--LIDAR LINK-->
  <link
    name="lidar_link">
    <inertial>
      <origin
        xyz="0 0 0"
        rpy="0 0 0" />
      <mass
        value="0.01" />
      <inertia
        ixx="0.001761"
        ixy="0"
        ixz="-2.9827E-36"
        iyy="0.001761"
        iyz="5.8775E-36"
        izz="0.0032799" />
    </inertial>
    <visual>
      <origin
        xyz="0 0 0"
        rpy="0 0 0" />
      <geometry>
        <mesh
          filename="package://robot_package/meshes/lidar_link.STL" />
      </geometry>
      <material
        name="">
        <color
          rgba="0.79216 0.81961 0.93333 1" />
      </material>
    </visual>
    <collision>
      <origin
        xyz="0 0 0"
        rpy="0 0 0" />
      <geometry>
        <mesh
          filename="package://robot_package/meshes/lidar_link.STL" />
      </geometry>
    </collision>
  </link>

  <!--LIDAR JOINT-->
  <joint
    name="lidar_joint"
    type="fixed">
    <origin
      xyz="0.125 0 0.17"
      rpy="0 0 0" />
    <parent
      link="body_link" />
    <child
      link="lidar_link" />
    <axis
      xyz="0 0 0" />
  </joint>

  <!--IR SENSOR LINK 1-->
  <link
    name="IR_sensor1_link">
    <inertial>
      <origin
        xyz="5.5511E-17 0 -0.01"
        rpy="0 0 0" />
      <mass
        value="0.1" />
      <inertia
        ixx="3.6652E-07"
        ixy="0"
        ixz="-1.2142E-39"
        iyy="3.6652E-07"
        iyz="1.1479E-39"
        izz="3.1416E-07" />
    </inertial>
    <visual>
      <origin
        xyz="0 0 0"
        rpy="0 0 0" />
      <geometry>
        <mesh
          filename="package://robot_package/meshes/IR_sensor1_link.STL" />
      </geometry>
      <material
        name="">
        <color
          rgba="1 1 0 1" />
      </material>
    </visual>
    <collision>
      <origin
        xyz="0 0 0"
        rpy="0 0 0" />
      <geometry>
        <mesh
          filename="package://robot_package/meshes/IR_sensor1_link.STL" />
      </geometry>
    </collision>
  </link>

  <!--IR SENSOR JOINT 1-->
  <joint
    name="IR_sensor1_joint"
    type="fixed">
    <origin
      xyz="0.7 -0.0525 -0.02"
      rpy="0 1.5708 0" />
    <parent
      link="body_link" />
    <child
      link="IR_sensor1_link" />
    <axis
      xyz="0 0 0" />
  </joint>

  <!--IR SENSOR LINK 2-->
  <link
    name="IR_sensor2_link">
    <inertial>
      <origin
        xyz="5.5511E-17 0 -0.01"
        rpy="0 0 0" />
      <mass
        value="0.1" />
      <inertia
        ixx="3.6652E-07"
        ixy="0"
        ixz="-1.2142E-39"
        iyy="3.6652E-07"
        iyz="1.1479E-39"
        izz="3.1416E-07" />
    </inertial>
    <visual>
      <origin
        xyz="0 0 0"
        rpy="0 0 0" />
      <geometry>
        <mesh
          filename="package://robot_package/meshes/IR_sensor2_link.STL" />
      </geometry>
      <material
        name="">
        <color
          rgba="1 1 0 1" />
      </material>
    </visual>
    <collision>
      <origin
        xyz="0 0 0"
        rpy="0 0 0" />
      <geometry>
        <mesh
          filename="package://robot_package/meshes/IR_sensor2_link.STL" />
      </geometry>
    </collision>
  </link>

  <!--IR SENSOR JOINT 2-->
  <joint
    name="IR_sensor2_joint"
    type="fixed">
    <origin
      xyz="0.7 -0.0175 -0.02"
      rpy="0 1.5708 0" />
    <parent
      link="body_link" />
    <child
      link="IR_sensor2_link" />
    <axis
      xyz="0 0 0" />
  </joint>

  <!--IR SENSOR LINK 3-->
  <link
    name="IR_sensor3_link">
    <inertial>
      <origin
        xyz="0 0 -0.01"
        rpy="0 0 0" />
      <mass
        value="0.1" />
      <inertia
        ixx="3.6652E-07"
        ixy="3.9827E-55"
        ixz="-1.2142E-39"
        iyy="3.6652E-07"
        iyz="-1.538E-38"
        izz="3.1416E-07" />
    </inertial>
    <visual>
      <origin
        xyz="0 0 0"
        rpy="0 0 0" />
      <geometry>
        <mesh
          filename="package://robot_package/meshes/IR_sensor3_link.STL" />
      </geometry>
      <material
        name="">
        <color
          rgba="1 1 0 1" />
      </material>
    </visual>
    <collision>
      <origin
        xyz="0 0 0"
        rpy="0 0 0" />
      <geometry>
        <mesh
          filename="package://robot_package/meshes/IR_sensor3_link.STL" />
      </geometry>
    </collision>
  </link>

  <!--IR SENSOR JOINT 3-->
  <joint
    name="IR_sensor3_joint"
    type="fixed">
    <origin
      xyz="0.7 0.0175 -0.02"
      rpy="0 1.5708 0" />
    <parent
      link="body_link" />
    <child
      link="IR_sensor3_link" />
    <axis
      xyz="0 0 0" />
  </joint>

  <!--IR SENSOR LINK 4-->
  <link
    name="IR_sensor4_link">
    <inertial>
      <origin
        xyz="5.5511E-17 0 -0.01"
        rpy="0 0 0" />
      <mass
        value="0.1" />
      <inertia
        ixx="3.6652E-07"
        ixy="0"
        ixz="-1.2142E-39"
        iyy="3.6652E-07"
        iyz="1.1479E-39"
        izz="3.1416E-07" />
    </inertial>
    <visual>
      <origin
        xyz="0 0 0"
        rpy="0 0 0" />
      <geometry>
        <mesh
          filename="package://robot_package/meshes/IR_sensor4_link.STL" />
      </geometry>
      <material
        name="">
        <color
          rgba="1 1 0 1" />
      </material>
    </visual>
    <collision>
      <origin
        xyz="0 0 0"
        rpy="0 0 0" />
      <geometry>
        <mesh
          filename="package://robot_package/meshes/IR_sensor4_link.STL" />
      </geometry>
    </collision>
  </link>

  <!--IR SENSOR JOINT 4-->
  <joint
    name="IR_sensor4_joint"
    type="fixed">
    <origin
      xyz="0.7 0.0525 -0.02"
      rpy="0 1.5708 0" />
    <parent
      link="body_link" />
    <child
      link="IR_sensor4_link" />
    <axis
      xyz="0 0 0" />
  </joint>
</robot>