<?xml version="1.0" encoding="utf-8"?>
<!-- This URDF was automatically created by SolidWorks to URDF Exporter! Originally created by Stephen Brawner (brawner@gmail.com) 
     Commit Version: 1.6.0-1-g15f4949  Build Version: 1.6.7594.29634
     For more information, please see http://wiki.ros.org/sw_urdf_exporter -->
<robot
  name="robot_package">

  <link name="base_link">
    <origin xyz="0.0837309089334095 0 -0.005"/>
  </link>

    <joint name="body_joint" type="fixed">
      <parent link="base_link"/>
      <child link="body_link"/>
      <origin xyz="0.0837309089334095 0 -0.005"/>
    </joint>

    <link name="body_link">
    <inertial>
      <origin
        xyz="0.0837309089334095 0 -0.005"
        rpy="0 0 0" />
      <mass
        value="0.135560486526924" />
      <inertia
        ixx="8.99650928849354E-05"
        ixy="-3.6875275332451E-20"
        ixz="2.10960298165725E-21"
        iyy="0.0003117677496315"
        iyz="-6.11966463910784E-22"
        izz="0.000399486795574482" />
    </inertial>
    <visual>
      <origin
        xyz="0 0 0"
        rpy="0 0 0" />
      <geometry>
        <mesh
          filename="package://robot_package/meshes/body_link.STL" />
      </geometry>
      <material
        name="">
        <color
          rgba="1 0.168627450980392 0.168627450980392 1" />
      </material>
    </visual>
    <collision>
      <origin
        xyz="0 0 0"
        rpy="0 0 0" />
      <geometry>
        <mesh
          filename="package://robot_package/meshes/body_link.STL" />
      </geometry>
    </collision>
  </link>

  <link
    name="wheel_left_link">
    <inertial>
      <origin
        xyz="5.5511E-17 -4.1633E-17 0.0125"
        rpy="0 0 0" />
      <mass
        value="0.046482" />
      <inertia
        ixx="1.7338E-05"
        ixy="2.3928E-20"
        ixz="-1.576E-21"
        iyy="1.7338E-05"
        iyz="-1.2557E-22"
        izz="3.0897E-05" />
    </inertial>
    <visual>
      <origin
        xyz="0 0 0"
        rpy="0 0 0" />
      <geometry>
        <mesh
          filename="package://robot_package/meshes/wheel_left_link.STL" />
      </geometry>
      <material
        name="">
        <color
          rgba="0.039216 0.4902 0.7098 1" />
      </material>
    </visual>
    <collision>
      <origin
        xyz="0 0 0"
        rpy="0 0 0" />
      <geometry>
        <mesh
          filename="package://robot_package/meshes/wheel_left_link.STL" />
      </geometry>
    </collision>
  </link>

  <joint
    name="wheel_left_joint"
    type="continuous">
    <parent
      link="base_link" />
    <child
      link="wheel_left_link" />    
    <origin
      xyz="0.025 0.04 -0.005"
      rpy="-1.5708 0 0" />
    <axis
      xyz="0 0 -1" />
  </joint>

  <link
    name="wheel_right_link">
    <inertial>
      <origin
        xyz="5.5511E-17 4.1633E-17 0.0125"
        rpy="0 0 0" />
      <mass
        value="0.046482" />
      <inertia
        ixx="1.7338E-05"
        ixy="-2.4478E-20"
        ixz="1.5487E-21"
        iyy="1.7338E-05"
        iyz="-4.9773E-22"
        izz="3.0897E-05" />
    </inertial>
    <visual>
      <origin
        xyz="0 0 0"
        rpy="0 0 0" />
      <geometry>
        <mesh
          filename="package://robot_package/meshes/wheel_right_link.STL" />
      </geometry>
      <material
        name="">
        <color
          rgba="0.039216 0.4902 0.7098 1" />
      </material>
    </visual>
    <collision>
      <origin
        xyz="0 0 0"
        rpy="0 0 0" />
      <geometry>
        <mesh
          filename="package://robot_package/meshes/wheel_right_link.STL" />
      </geometry>
    </collision>
  </link>

  <joint
    name="wheel_right_joint"
    type="continuous">
    <origin
      xyz="0.025 -0.04 -0.005"
      rpy="1.5708 0 0" />
    <parent
      link="base_link" />
    <child
      link="wheel_right_link" />
    <axis
      xyz="0 0 1" />
  </joint>

  <link
    name="caster_wheel_link">
    <inertial>
      <origin
        xyz="0 0 0"
        rpy="0 0 0" />
      <mass
        value="0" />
      <inertia
        ixx="0"
        ixy="0"
        ixz="0"
        iyy="0"
        iyz="0"
        izz="0" />
    </inertial>
    <visual>
      <origin
        xyz="0 0 0"
        rpy="0 0 0" />
      <geometry>
        <mesh
          filename="package://robot_package/meshes/caster_wheel_link.STL" />
      </geometry>
      <material
        name="">
        <color
          rgba="1 1 1 1" />
      </material>
    </visual>
    <collision>
      <origin
        xyz="0 0 0"
        rpy="0 0 0" />
      <geometry>
        <mesh
          filename="package://robot_package/meshes/caster_wheel_link.STL" />
      </geometry>
    </collision>
  </link>

  <joint
    name="caster_wheel_joint"
    type="fixed">
    <origin
      xyz="0.12 0 0"
      rpy="0 0 0" />
    <parent
      link="body_link" />
    <child
      link="caster_wheel_link" />
    <axis
      xyz="0 0 1" />
  </joint>
</robot>